<?xml version="1.0" ?>
<!-- =================================================================================== -->
<!-- |    This document was autogenerated by xacro from rebearm.urdf.xacro             | -->
<!-- |    EDITING THIS FILE BY HAND IS NOT RECOMMENDED                                 | -->
<!-- =================================================================================== -->
<!-- |    Manually replace package://rebearm_description/meshes ->  assets             | -->
<!-- =================================================================================== -->
<!-- Revolute-Revolute Manipulator -->
<robot name="rebearm">
  <material name="black">
    <color rgba="0.0 0.0 0.0 0.9"/>
  </material>
  <material name="blue">
    <color rgba="0.0 0.0 0.8 1.0"/>
  </material>
  <material name="green">
    <color rgba="0.0 0.8 0.0 1.0"/>
  </material>
  <material name="grey">
    <color rgba="0.2 0.2 0.2 0.9"/>
  </material>
  <material name="orange">
    <color rgba="1.0 0.4235294117647059 0.0392156862745098 0.9"/>
  </material>
  <material name="brown">
    <color rgba="0.8705882352941177 0.8117647058823529 0.7647058823529411 0.9"/>
  </material>
  <material name="red">
    <color rgba="0.8 0.0 0.0 1.0"/>
  </material>
  <material name="yellow">
    <color rgba="1.0 1.0 0.0 0.9"/>
  </material>
  <material name="white">
    <color rgba="1.0 1.0 1.0 0.9"/>
  </material>
  <!-- Used for fixing robot -->
  <link name="world"/>
  <gazebo reference="world">
    <static>true</static>
  </gazebo>
  <!-- World fixed joint-->
  <joint name="world_fixed" type="fixed">
    <origin rpy="0 0 0" xyz="0 0 0"/>
    <parent link="world"/>
    <child link="base_link"/>
  </joint>
  <!-- arbitrary value for mass -->
  <!-- Space btw top of beam and the each joint -->
  <!-- Base Link -->
  <link name="base_link">
    <collision>
      <origin rpy="0.0 0.0 0.0" xyz="-0.245 -0.45 0.0"/>
      <geometry>
        <box size="0.44 0.44 0.28"/>
      </geometry>
    </collision>
    <visual>
      <origin rpy="0.0 0.0 0.0" xyz="-0.245 -0.45 0.0"/>
      <geometry>
        <mesh filename="assets/URDF_joint0.stl" scale="0.005 0.005 0.005"/>
      </geometry>
      <material name="grey"/>
    </visual>
    <inertial>
      <origin rpy="0.0 0.0 0.0" xyz="0.0 0.0 0.0"/>
      <mass value="1"/>
      <inertia ixx="1.0" ixy="0.0" ixz="0.0" iyy="1.0" iyz="0.0" izz="1.0"/>
    </inertial>
  </link>
  <!-- Joint 1, z origin = parent height -->
  <joint name="joint1" type="revolute">
    <parent link="base_link"/>
    <child link="link1"/>
    <origin rpy="0.0 0.0 0.0" xyz="0.0 0.0 0.2"/>
    <axis xyz="0 0 1"/>
    <dynamics damping="0.7"/>
    <limit effort="1" lower="-1.57" upper="1.57" velocity="4.8"/>
  </joint>
  <!-- Link 1-->
  <link name="link1">
    <collision>
      <origin rpy="-0.1 -0.33 0.0" xyz="0 0 0"/>
      <geometry>
        <box size="0.2 0.2 0.45"/>
      </geometry>
    </collision>
    <visual>
      <origin rpy="0.0 0.0 0" xyz="-0.1  -0.33 0.0"/>
      <geometry>
        <mesh filename="assets/URDF_joint1.stl" scale="0.005 0.005 0.005"/>
      </geometry>
      <material name="white"/>
    </visual>
    <inertial>
      <origin rpy="0.0 0.0 0.0" xyz="0 0 0.225"/>
      <mass value="1"/>
      <inertia ixx="0.020208333333333335" ixy="0.0" ixz="0.0" iyy="0.020208333333333335" iyz="0.0" izz="0.006666666666666668"/>
    </inertial>
  </link>
  <!-- Joint 2, z origin = parent height -->
  <joint name="joint2" type="revolute">
    <parent link="link1"/>
    <child link="link2"/>
    <origin rpy="0.0 0.0 0.0" xyz="0.0 0.0 0.19"/>
    <filename xyz="-1 0 0"/>
    <dynamics damping="0.7"/>
    <limit effort="1" lower="0.52" upper="-0.105" velocity="4.8"/>
  </joint>
  <!-- Link 2-->
  <link name="link2">
    <collision>
      <origin rpy="0.0 0.0 0.0" xyz="-0.11 -0.29 -0.05"/>
      <geometry>
        <box size="0.2 0.2 0.58"/>
      </geometry>
    </collision>
    <visual>
      <origin rpy="0.0 0.0 0.0" xyz="-0.11 -0.29 -0.05"/>
      <geometry>
        <mesh filename="assets/URDF_joint2.stl" scale="0.005 0.005 0.005"/>
      </geometry>
      <material name="orange"/>
    </visual>
    <inertial>
      <origin rpy="0.0 0.0 0.0" xyz="0 0 0"/>
      <mass value="1"/>
      <inertia ixx="0.03136666666666666" ixy="0.0" ixz="0.0" iyy="0.03136666666666666" iyz="0.0" izz="0.006666666666666668"/>
    </inertial>
  </link>
  <!-- Joint 3, z origin = parent height  -->
  <joint name="joint3" type="revolute">
    <parent link="link2"/>
    <child link="link3"/>
    <origin rpy="0.0 0.0 0.0" xyz="0.0 0.0 0.44"/>
    <axis xyz="1 0 0"/>
    <dynamics damping="0.7"/>
    <limit effort="1" lower="-0.78" upper="-2.09" velocity="4.8"/>
  </joint>
  <!-- Link 3 -->
  <link name="link3">
    <collision>
      <origin rpy="0.0  0.0 3.141592653589793" xyz="0.11 0.24 -0.05"/>
      <geometry>
        <box size="0.2 0.2 0.4"/>
      </geometry>
    </collision>
    <visual>
      <origin rpy="0.0 0.0 3.141592653589793" xyz="0.11 0.24 -0.05"/>
      <geometry>
        <mesh filename="assets/URDF_joint3.stl" scale="0.005 0.005 0.005"/>
      </geometry>
      <material name="green"/>
    </visual>
    <inertial>
      <origin rpy="0.0 0.0 0.0" xyz="0 0 0"/>
      <mass value="1"/>
      <inertia ixx="0.01666666666666667" ixy="0.0" ixz="0.0" iyy="0.01666666666666667" iyz="0.0" izz="0.006666666666666668"/>
    </inertial>
  </link>
  <!-- Joint 4, z origin = parent height  -->
  <joint name="joint4" type="revolute">
    <origin rpy="0 0 0" xyz="0.0 -0.001 0.56"/>
    <parent link="link3"/>
    <child link="link4"/>
    <axis xyz="1 0 0"/>
    <dynamics damping="0.7"/>
    <limit effort="1" lower="-0.87" upper="-2.09" velocity="4.8"/>
  </joint>
  <!-- Link 4 -->
  <link name="link4">
    <collision>
      <origin rpy="0.0 0.0 0.0" xyz="-0.12 -0.43 -0.05"/>
      <geometry>
        <box size="0.2 0.2 0.065"/>
      </geometry>
    </collision>
    <visual>
      <origin rpy="0.0 0.0 0.0" xyz="-0.12 -0.43 -0.05"/>
      <geometry>
        <mesh filename="assets/URDF_joint4.stl" scale="0.005 0.005 0.005"/>
      </geometry>
      <material name="yellow"/>
    </visual>
    <inertial>
      <origin rpy="0.0 0.0 0.0" xyz="0 0 0"/>
      <mass value="1"/>
      <inertia ixx="0.003685416666666667" ixy="0.0" ixz="0.0" iyy="0.003685416666666667" iyz="0.0" izz="0.006666666666666668"/>
    </inertial>
  </link>
  <!-- Joint 5, z origin = parent height  -->
  <joint name="joint5" type="revolute">
    <origin rpy="0.0 0.0 0.0" xyz="0.0 -0.06 0.3"/>
    <parent link="link4"/>
    <child link="link5"/>
    <axis xyz="0 0 1"/>
    <dynamics damping="0.7"/>
    <limit effort="1" lower="1.5707963267948966" upper="-1.5707963267948966" velocity="4.8"/>
  </joint>
  <!-- Link 5, gripper base -->
  <link name="link5">
    <collision>
      <origin rpy="0.0 0.0 0.0" xyz="-0.12 -0.166 0.0"/>
      <geometry>
        <box size="0.045 0.045 0.95"/>
      </geometry>
    </collision>
    <visual>
      <origin rpy="0.0 0.0 0.0 " xyz="-0.12 -0.166 0.0"/>
      <geometry>
        <mesh filename="assets/URDF_joint5.stl" scale="0.005 0.005 0.005"/>
      </geometry>
      <material name="blue"/>
    </visual>
    <inertial>
      <origin rpy="0.0 0.0 0.0" xyz="0 0 0"/>
      <mass value="1"/>
      <inertia ixx="0.003685416666666667" ixy="0.0" ixz="0.0" iyy="0.003685416666666667" iyz="0.0" izz="0.006666666666666668"/>
    </inertial>
  </link>
  <!-- Joint 6, z origin = parent height  -->
  <joint name="joint6" type="revolute">
    <origin rpy="0.0 0.0 0.0" xyz="0.0 -0.07 0.178"/>
    <parent link="link5"/>
    <child link="link6"/>
    <axis xyz="1 0 0"/>
    <dynamics damping="0.7"/>
    <limit effort="1" lower="-1.6" upper="-1.04" velocity="4.8"/>
  </joint>
  <!-- Link 6, gripper mover -->
  <link name="link6">
    <collision>
      <origin rpy="1.5707963267948966 0.0 0.0" xyz="-0.12 0.053 -0.05"/>
      <geometry>
        <box size="0.045 0.045 0.95"/>
      </geometry>
    </collision>
    <visual>
      <origin rpy="1.5707963267948966 0.0 0.0" xyz="-0.12 0.053 -0.05"/>
      <geometry>
        <mesh filename="assets/URDF_joint6.stl" scale="0.005 0.005 0.005"/>
      </geometry>
      <material name="blue"/>
    </visual>
    <inertial>
      <origin rpy="0.0 0.0 0.0" xyz="0 0 0"/>
      <mass value="1"/>
      <inertia ixx="0.003685416666666667" ixy="0.0" ixz="0.0" iyy="0.003685416666666667" iyz="0.0" izz="0.006666666666666668"/>
    </inertial>
  </link>
  <ros2_control name="rebearm" type="system">
    <hardware>
      <plugin>rebearm_hardware/rebearmSystemPositionOnlyHardware</plugin>
      <param name="example_param_hw_start_duration_sec">0</param>
      <param name="example_param_hw_stop_duration_sec">3.0</param>
      <param name="example_param_hw_slowdown">100</param>
    </hardware>
    <joint name="joint1">
      <command_interface name="position">
        <param name="min">-1</param>
        <param name="max">1</param>
      </command_interface>
      <state_interface name="position"/>
    </joint>
    <joint name="joint2">
      <command_interface name="position">
        <param name="min">-1</param>
        <param name="max">1</param>
      </command_interface>
      <state_interface name="position"/>
    </joint>
    <joint name="joint3">
      <command_interface name="position">
        <param name="min">-1</param>
        <param name="max">1</param>
      </command_interface>
      <state_interface name="position"/>
    </joint>
    <joint name="joint4">
      <command_interface name="position">
        <param name="min">-1</param>
        <param name="max">1</param>
      </command_interface>
      <state_interface name="position"/>
    </joint>
    <joint name="joint5">
      <command_interface name="position">
        <param name="min">-1</param>
        <param name="max">1</param>
      </command_interface>
      <state_interface name="position"/>
    </joint>
    <joint name="joint6">
      <command_interface name="position">
        <param name="min">-1</param>
        <param name="max">1</param>
      </command_interface>
      <state_interface name="position"/>
    </joint>
  </ros2_control>
</robot>
